<?xml version="1.0"?>
<robot
    xmlns:xacro="http://ros.org/wiki/xacro"
    name="wheel_steered">
  <xacro:include filename="$(arg gazebo_ros_four_wheel_steering_prefix)/urdf/primitives.urdf.xacro" />
  <xacro:property
      name="axle_link_radius"
      value="0.1" />
  <xacro:property
      name="steering_link_mass"
      value="10.0" />

  <xacro:macro
      name="wheel_steered"
      params="prefix parent_link left_right *origin">
    <link name="${prefix}_axle">
      <xacro:sphere_primitive radius="${axle_link_radius}" />
      <xacro:sphere_inertial_with_origin
          radius="${axle_link_radius}"
          mass="${steering_link_mass}">
        <origin xyz="0 ${-0.1 * left_right} 0" />
      </xacro:sphere_inertial_with_origin>
    </link>

    <joint
        name="${prefix}_kingpin"
        type="revolute">
      <limit
          lower="-0.6"
          upper="0.6"
          effort="4000"
          velocity="1.0" />
      <axis xyz="0 0 1" />
      <parent link="${parent_link}" />
      <child link="${prefix}_axle" />
      <xacro:insert_block name="origin" />
      <dynamics friction="0" />
      <gazebo>
        <physics>
          <ode>
            <cfm_damping>1</cfm_damping>
          </ode>
        </physics>
      </gazebo>
    </joint>
  </xacro:macro>
</robot>
